Workbook

Sheet test_42
A1: 1 | B1: -53
A2: 2 | B2: -66 | S2: SUMMARY OUTPUT
A3: 3 | B3: -36
A4: 4 | B4: 81 | S4: Regression Statistics
A5: 5 | B5: -8 | S5: Multiple R | T5: 0.99960693
A6: 6 | B6: -48 | S6: R Square | T6: 0.99921401
A7: 7 | B7: -45 | S7: Adjusted R Square | T7: 0.9992128
A8: 8 | B8: 48 | S8: Standard Error | T8: 20.873778
A9: 9 | B9: 67 | S9: Observations | T9: 653
A10: 10 | B10: -30
A11: 11 | B11: -32 | S11: ANOVA
A12: 12 | B12: -2 | T12: df | U12: SS | V12: MS | W12: F | X12: Significance F
A13: 13 | B13: 49 | S13: Regression | T13: 1 | U13: 3.6059815e+08 | V13: 3.6059815e+08 | W13: 827601.66 | X13: 0
A14: 14 | B14: -13 | S14: Residual | T14: 651 | U14: 283650.22 | V14: 435.71463
A15: 15 | B15: -19 | S15: Total | T15: 652 | U15: 3.608818e+08
A16: 16 | B16: -5
A17: 17 | B17: 54 | T17: Coefficients | U17: Standard Error | V17: t Stat | W17: P-value | X17: Lower 95% | Y17: Upper 95% | Z17: Lower 95.0% | AA17: Upper 95.0%
A18: 18 | B18: 23 | S18: Intercept | T18: -66.425972 | U18: 1.6355863 | V18: -40.612941 | W18: 1.3179583e-180 | X18: -69.637633 | Y18: -63.21431 | Z18: -69.637633 | AA18: -63.21431
A19: 19 | B19: -1 | S19: X Variable 1 | T19: 3.9421497 | U19: 0.0043333367 | V19: 909.72615 | W19: 0 | X19: 3.9336407 | Y19: 3.9506587 | Z19: 3.9336407 | AA19: 3.9506587
A20: 20 | B20: 11
A21: 21 | B21: 51 | T21: =T19/100*36000 -> 1419.1739
A22: 22 | B22: 68
A23: 23 | B23: 17
A24: 24 | B24: 51
A25: 25 | B25: 88
A26: 26 | B26: 39
A27: 27 | B27: 34
A28: 28 | B28: 47
A29: 29 | B29: 107
A30: 30 | B30: 77
A31: 31 | B31: 52
A32: 32 | B32: 53
A33: 33 | B33: 111
... A653: 653 | B653: 2502

Sheet test_39
A1: 1 | B1: 2
A2: 2 | B2: 9 | S2: SUMMARY OUTPUT
A3: 3 | B3: 15
A4: 4 | B4: 26 | S4: Regression Statistics
A5: 5 | B5: 23 | S5: Multiple R | T5: 0.9993456
A6: 6 | B6: 21 | S6: R Square | T6: 0.99869163
A7: 7 | B7: 27 | S7: Adjusted R Square | T7: 0.99868816
A8: 8 | B8: 30 | S8: Standard Error | T8: 15.7489
A9: 9 | B9: 32 | S9: Observations | T9: 379
A10: 10 | B10: 45
A11: 11 | B11: 43 | S11: ANOVA
A12: 12 | B12: 45 | T12: df | U12: SS | V12: MS | W12: F | X12: Significance F
A13: 13 | B13: 54 | S13: Regression | T13: 1 | U13: 71374697 | V13: 71374697 | W13: 287768.87 | X13: 0
A14: 14 | B14: 56 | S14: Residual | T14: 377 | U14: 93506.504 | V14: 248.02786
A15: 15 | B15: 54 | S15: Total | T15: 378 | U15: 71468203
A16: 16 | B16: 63
A17: 17 | B17: 64 | T17: Coefficients | U17: Standard Error | V17: t Stat | W17: P-value | X17: Lower 95% | Y17: Upper 95% | Z17: Lower 95.0% | AA17: Upper 95.0%
A18: 18 | B18: 71 | S18: Intercept | T18: 0.80646647 | U18: 1.6211404 | V18: 0.49746863 | W18: 0.61914863 | X18: -2.3811435 | Y18: 3.9940765 | Z18: -2.3811435 | AA18: 3.9940765
A19: 19 | B19: 71 | S19: X Variable 1 | T19: 3.9664817 | U19: 0.00739407 | V19: 536.44092 | W19: 0 | X19: 3.9519429 | Y19: 3.9810205 | Z19: 3.9519429 | AA19: 3.9810205
A20: 20 | B20: 75
A21: 21 | B21: 82 | T21: =T19/100*36000 -> 1427.9334
A22: 22 | B22: 103
A23: 23 | B23: 103
A24: 24 | B24: 92
A25: 25 | B25: 97
A26: 26 | B26: 101
A27: 27 | B27: 106
A28: 28 | B28: 111
A29: 29 | B29: 109
A30: 30 | B30: 117
A31: 31 | B31: 114
A32: 32 | B32: 126
A33: 33 | B33: 136
... A379: 379 | B379: 1501

Sheet test_31
A1: 1 | B1: 2
A2: 2 | B2: 9 | S2: SUMMARY OUTPUT
A3: 3 | B3: 11
A4: 4 | B4: 17 | S4: Regression Statistics
A5: 5 | B5: 19 | S5: Multiple R | T5: 0.99686384
A6: 6 | B6: 30 | S6: R Square | T6: 0.99373752
A7: 7 | B7: 28 | S7: Adjusted R Square | T7: 0.99372082
A8: 8 | B8: 31 | S8: Standard Error | T8: 34.487461
A9: 9 | B9: 32 | S9: Observations | T9: 377
A10: 10 | B10: 37
A11: 11 | B11: 42 | S11: ANOVA
A12: 12 | B12: 49 | T12: df | U12: SS | V12: MS | W12: F | X12: Significance F
A13: 13 | B13: 53 | S13: Regression | T13: 1 | U13: 70774897 | V13: 70774897 | W13: 59505.459 | X13: 0
A14: 14 | B14: 52 | S14: Residual | T14: 375 | U14: 446019.36 | V14: 1189.385
A15: 15 | B15: 57 | S15: Total | T15: 376 | U15: 71220917
A16: 16 | B16: 91
A17: 17 | B17: 246 | T17: Coefficients | U17: Standard Error | V17: t Stat | W17: P-value | X17: Lower 95% | Y17: Upper 95% | Z17: Lower 95.0% | AA17: Upper 95.0%
A18: 18 | B18: 128 | S18: Intercept | T18: 9.2328856 | U18: 3.559468 | V18: 2.5938948 | W18: 0.0098613621 | X18: 2.2338675 | Y18: 16.231904 | Z18: 2.2338675 | AA18: 16.231904
A19: 19 | B19: 67 | S19: X Variable 1 | T19: 3.9812527 | U19: 0.016320796 | V19: 243.93741 | W19: 0 | X19: 3.949161 | Y19: 4.0133445 | Z19: 3.949161 | AA19: 4.0133445
A20: 20 | B20: 74
A21: 21 | B21: 79 | T21: =T19/100*36000 -> 1433.251
A22: 22 | B22: 84
A23: 23 | B23: 85
A24: 24 | B24: 91
A25: 25 | B25: 91
A26: 26 | B26: 99
A27: 27 | B27: 105
A28: 28 | B28: 103
A29: 29 | B29: 111
A30: 30 | B30: 117
A31: 31 | B31: 117
A32: 32 | B32: 128
A33: 33 | B33: 135
... A377: 377 | B377: 1501

Sheet test_30
A1: 1 | B1: 18
A2: 2 | B2: 18 | S2: SUMMARY OUTPUT
A3: 3 | B3: 24
A4: 4 | B4: 28 | S4: Regression Statistics
A5: 5 | B5: 37 | S5: Multiple R | T5: 0.99654404
A6: 6 | B6: 42 | S6: R Square | T6: 0.99310003
A7: 7 | B7: 57 | S7: Adjusted R Square | T7: 0.99308706
A8: 8 | B8: 62 | S8: Standard Error | T8: 95.298231
A9: 9 | B9: 70 | S9: Observations | T9: 534
A10: 10 | B10: 75
A11: 11 | B11: 80 | S11: ANOVA
A12: 12 | B12: 93 | T12: df | U12: SS | V12: MS | W12: F | X12: Significance F
A13: 13 | B13: 100 | S13: Regression | T13: 1 | U13: 6.9538783e+08 | V13: 6.9538783e+08 | W13: 76569.781 | X13: 0
A14: 14 | B14: 109 | S14: Residual | T14: 532 | U14: 4831492.5 | V14: 9081.7529
A15: 15 | B15: 113 | S15: Total | T15: 533 | U15: 7.0021932e+08
A16: 16 | B16: 119
A17: 17 | B17: 134 | T17: Coefficients | U17: Standard Error | V17: t Stat | W17: P-value | X17: Lower 95% | Y17: Upper 95% | Z17: Lower 95.0% | AA17: Upper 95.0%
A18: 18 | B18: 132 | S18: Intercept | T18: 44.478045 | U18: 8.2595133 | V18: 5.3850684 | W18: 1.0885241e-07 | X18: 28.252783 | Y18: 60.703306 | Z18: 28.252783 | AA18: 60.703306
A19: 19 | B19: 141 | S19: X Variable 1 | T19: 7.4027493 | U19: 0.026752498 | V19: 276.71245 | W19: 0 | X19: 7.3501958 | Y19: 7.4553028 | Z19: 7.3501958 | AA19: 7.4553028
A20: 20 | B20: 146
A21: 21 | B21: 157 | T21: =T19/100*36000 -> 2664.9897
A22: 22 | B22: 163
A23: 23 | B23: 171
A24: 24 | B24: 178
A25: 25 | B25: 197
A26: 26 | B26: 201
A27: 27 | B27: 200
A28: 28 | B28: 205
A29: 29 | B29: 213
A30: 30 | B30: 218
A31: 31 | B31: 233
A32: 32 | B32: 243
A33: 33 | B33: 246
... A534: 534 | B534: 4007

Sheet test_20
A1: 1 | B1: 6
A2: 2 | B2: 22 | S2: SUMMARY OUTPUT
A3: 3 | B3: 24
A4: 4 | B4: 26 | S4: Regression Statistics
A5: 5 | B5: 34 | S5: Multiple R | T5: 0.99940122
A6: 6 | B6: 37 | S6: R Square | T6: 0.99880279
A7: 7 | B7: 50 | S7: Adjusted R Square | T7: 0.99879919
A8: 8 | B8: 51 | S8: Standard Error | T8: 24.875375
A9: 9 | B9: 63 | S9: Observations | T9: 334
A10: 10 | B10: 67
A11: 11 | B11: 74 | S11: ANOVA
A12: 12 | B12: 79 | T12: df | U12: SS | V12: MS | W12: F | X12: Significance F
A13: 13 | B13: 92 | S13: Regression | T13: 1 | U13: 1.7139113e+08 | V13: 1.7139113e+08 | W13: 276980.43 | X13: 0
A14: 14 | B14: 98 | S14: Residual | T14: 332 | U14: 205436.38 | V14: 618.78428
A15: 15 | B15: 107 | S15: Total | T15: 333 | U15: 1.7159657e+08
A16: 16 | B16: 112
A17: 17 | B17: 118 | T17: Coefficients | U17: Standard Error | V17: t Stat | W17: P-value | X17: Lower 95% | Y17: Upper 95% | Z17: Lower 95.0% | AA17: Upper 95.0%
A18: 18 | B18: 132 | S18: Intercept | T18: 10.714031 | U18: 2.7283642 | V18: 3.9269066 | W18: 0.00010466752 | X18: 5.3469705 | Y18: 16.081092 | Z18: 5.3469705 | AA18: 16.081092
A19: 19 | B19: 130 | S19: X Variable 1 | T19: 7.4296276 | U19: 0.014117003 | V19: 526.2893 | W19: 0 | X19: 7.4018575 | Y19: 7.4573976 | Z19: 7.4018575 | AA19: 7.4573976
A20: 20 | B20: 142
A21: 21 | B21: 147 | T21: =T19/100*36000 -> 2674.6659
A22: 22 | B22: 165
A23: 23 | B23: 186
A24: 24 | B24: 179
A25: 25 | B25: 179
A26: 26 | B26: 185
A27: 27 | B27: 194
A28: 28 | B28: 195
A29: 29 | B29: 210
A30: 30 | B30: 223
A31: 31 | B31: 228
A32: 32 | B32: 240
A33: 33 | B33: 244
... A334: 334 | B334: 2502

Sheet list
A1: # of test | B1: flow | C1: target | D1: time | E1: grav flow | F1: manual flow | H1: manual flow test | I1: flow from chart
A2: 1 | B2: 4 | C2: 15 | D2: 198 | E2: =C2/D2*36000 -> 2727.2727 | F2: 2710 | G2: =(E2-F2)/F2 -> 0.0063737001 | H2: 2710
A3: 2 | B3: 4 | C3: 15 | D3: 200 | E3: =C3/D3*36000 -> 2700 | F3: 2710 | G3: =(E3-F3)/F3 -> -0.0036900369
A4: 3 | B4: 4 | C4: 15 | D4: 200 | E4: =C4/D4*36000 -> 2700 | F4: 2710 | G4: =(E4-F4)/F4 -> -0.0036900369
A5: 4 | B5: 4 | C5: 15 | D5: 206 | E5: =C5/D5*36000 -> 2621.3592 | F5: 2710 | G5: =(E5-F5)/F5 -> -0.032708774
A6: 5 | B6: 4 | C6: 15 | D6: 201 | E6: =C6/D6*36000 -> 2686.5672 | F6: 2710 | G6: =(E6-F6)/F6 -> -0.0086468029
A7: 6 | B7: 4 | C7: 15 | D7: 214 | E7: =C7/D7*36000 -> 2523.3645 | F7: 2710 | G7: =(E7-F7)/F7 -> -0.068869193
A8: 7 | B8: 4 | C8: 15 | D8: 201 | E8: =C8/D8*36000 -> 2686.5672 | F8: 2710 | G8: =(E8-F8)/F8 -> -0.0086468029
A9: 8 | B9: 4 | C9: 15 | D9: 201 | E9: =C9/D9*36000 -> 2686.5672 | F9: 2710 | G9: =(E9-F9)/F9 -> -0.0086468029
A10: 9 | B10: 4 | C10: 15 | D10: 200 | E10: =C10/D10*36000 -> 2700 | F10: 2710 | G10: =(E10-F10)/F10 -> -0.0036900369
A11: 10 | B11: 4 | C11: 15 | D11: 199 | E11: =C11/D11*36000 -> 2713.5678 | F11: 2710 | G11: =(E11-F11)/F11 -> 0.0013165458
A12: 11 | B12: 4 | C12: 25 | D12: 333 | E12: =C12/D12*36000 -> 2702.7027 | F12: 2710 | G12: =(E12-F12)/F12 -> -0.0026927296
A13: 12 | B13: 4 | C13: 25 | D13: 335 | E13: =C13/D13*36000 -> 2686.5672 | F13: 2710 | G13: =(E13-F13)/F13 -> -0.0086468029
A14: 13 | B14: 4 | C14: 25 | D14: 337 | E14: =C14/D14*36000 -> 2670.6231 | F14: 2710 | G14: =(E14-F14)/F14 -> -0.014530205
... A20: 19 | B20: 4 | C20: 25 | D20: 334 | E20: =C20/D20*36000 -> 2694.6108 | F20: 2710 | G20: =(E20-F20)/F20 -> -0.0056786795
A21: 20 | B21: 4 | C21: 25 | D21: 333 | E21: =C21/D21*36000 -> 2702.7027 | F21: 2710 | G21: =(E21-F21)/F21 -> -0.0026927296 | I21: =test_20!T21 -> 2674.6659
A22: 21 | B22: 4 | C22: 40 | D22: 534 | E22: =C22/D22*36000 -> 2696.6292 | F22: 2710 | G22: =(E22-F22)/F22 -> -0.0049338696
A23: 22 | B23: 4 | C23: 40 | D23: 530 | E23: =C23/D23*36000 -> 2716.9811 | F23: 2710 | G23: =(E23-F23)/F23 -> 0.0025760635
A24: 23 | B24: 4 | C24: 40 | D24: 534 | E24: =C24/D24*36000 -> 2696.6292 | F24: 2710 | G24: =(E24-F24)/F24 -> -0.0049338696
A25: 24 | B25: 4 | C25: 40 | D25: 534 | E25: =C25/D25*36000 -> 2696.6292 | F25: 2710 | G25: =(E25-F25)/F25 -> -0.0049338696
A26: 25 | B26: 4 | C26: 40 | D26: 535 | E26: =C26/D26*36000 -> 2691.5888 | F26: 2710 | G26: =(E26-F26)/F26 -> -0.0067938063
A27: 26 | B27: 4 | C27: 40 | D27: 533 | E27: =C27/D27*36000 -> 2701.6886 | F27: 2710 | G27: =(E27-F27)/F27 -> -0.0030669537
A28: 27 | B28: 4 | C28: 40 | D28: 536 | E28: =C28/D28*36000 -> 2686.5672 | F28: 2710 | G28: =(E28-F28)/F28 -> -0.0086468029
A29: 28 | B29: 4 | C29: 40 | D29: 532 | E29: =C29/D29*36000 -> 2706.7669 | F29: 2710 | G29: =(E29-F29)/F29 -> -0.0011930194
A30: 29 | B30: 4 | C30: 40 | D30: 536 | E30: =C30/D30*36000 -> 2686.5672 | F30: 2710 | G30: =(E30-F30)/F30 -> -0.0086468029
A31: 30 | B31: 4 | C31: 40 | D31: 534 | E31: =C31/D31*36000 -> 2696.6292 | F31: 2710 | G31: =(E31-F31)/F31 -> -0.0049338696 | H31: 2710 | I31: =test_30!T21 -> 2664.9897
A32: 31 | B32: 2 | C32: 15 | D32: 377 | E32: =C32/D32*36000 -> 1432.3607 | F32: 1430 | G32: =(E32-F32)/F32 -> 0.001650869 | H32: 1450 | I32: =test_31!T21 -> 1433.251
A33: 32 | B33: 2 | C33: 15 | D33: 379 | E33: =C33/D33*36000 -> 1424.8021 | F33: 1440 | G33: =(E33-F33)/F33 -> -0.01055409
A34: 33 | B34: 2 | C34: 15 | D34: 381 | E34: =C34/D34*36000 -> 1417.3228 | F34: 1440 | G34: =(E34-F34)/F34 -> -0.015748031
A35: 34 | B35: 2 | C35: 15 | D35: 376 | E35: =C35/D35*36000 -> 1436.1702 | F35: 1440 | G35: =(E35-F35)/F35 -> -0.0026595745
A36: 35 | B36: 2 | C36: 15 | D36: 377 | E36: =C36/D36*36000 -> 1432.3607 | F36: 1440 | G36: =(E36-F36)/F36 -> -0.0053050398
A37: 36 | B37: 2 | C37: 15 | D37: 380 | E37: =C37/D37*36000 -> 1421.0526 | F37: 1440 | G37: =(E37-F37)/F37 -> -0.013157895
A38: 37 | B38: 2 | C38: 15 | D38: 380 | E38: =C38/D38*36000 -> 1421.0526 | F38: 1440 | G38: =(E38-F38)/F38 -> -0.013157895
A39: 38 | B39: 2 | C39: 15 | D39: 380 | E39: =C39/D39*36000 -> 1421.0526 | F39: 1440 | G39: =(E39-F39)/F39 -> -0.013157895
A40: 39 | B40: 2 | C40: 15 | D40: 379 | E40: =C40/D40*36000 -> 1424.8021 | F40: 1440 | G40: =(E40-F40)/F40 -> -0.01055409 | I40: =test_39!T21 -> 1427.9334
A41: 40 | B41: 2 | C41: 15 | D41: 379 | E41: =C41/D41*36000 -> 1424.8021 | F41: 1440 | G41: =(E41-F41)/F41 -> -0.01055409
A42: 41 | B42: 2 | C42: 25 | D42: 630 | E42: =C42/D42*36000 -> 1428.5714 | F42: 1441 | G42: =(E42-F42)/F42 -> -0.0086249628
A43: 42 | B43: 2 | C43: 25 | D43: 652 | E43: =C43/D43*36000 -> 1380.3681 | F43: 1442 | G43: =(E43-F43)/F43 -> -0.04274057 | I43: =test_42!T21 -> 1419.1739
A44: 43 | B44: 2 | C44: 25 | D44: 634 | E44: =C44/D44*36000 -> 1419.5584 | F44: 1443 | G44: =(E44-F44)/F44 -> -0.016245073
A45: 44 | B45: 2 | C45: 25 | D45: 635 | E45: =C45/D45*36000 -> 1417.3228 | F45: 1444 | G45: =(E45-F45)/F45 -> -0.018474491
...
